False False
concurrent.futures.process._RemoteTraceback: 
"""
Traceback (most recent call last):
  File "/home/kpanthi/.conda/envs/drl/lib/python3.10/concurrent/futures/process.py", line 246, in _process_worker
    r = call_item.fn(*call_item.args, **call_item.kwargs)
  File "/home/kpanthi/.conda/envs/drl/lib/python3.10/concurrent/futures/process.py", line 205, in _process_chunk
    return [fn(*args) for args in chunk]
  File "/home/kpanthi/.conda/envs/drl/lib/python3.10/concurrent/futures/process.py", line 205, in <listcomp>
    return [fn(*args) for args in chunk]
  File "/home/kpanthi/dev/thesis/aquacrop-richards/aquacrop/simulation_script.py", line 113, in run_simulation_and_get_balance
    model_results_df, expobj = run_simulation(args)
  File "/home/kpanthi/dev/thesis/aquacrop-richards/aquacrop/simulation_script.py", line 107, in run_simulation
    model_os.run_model(till_termination=True)
  File "/home/kpanthi/dev/thesis/aquacrop-richards/aquacrop/aquacrop/core.py", line 316, in run_model
    ) = self._perform_timestep()
  File "/home/kpanthi/dev/thesis/aquacrop-richards/aquacrop/aquacrop/core.py", line 387, in _perform_timestep
    new_cond, param_struct, outputs = solution_single_time_step(
  File "/home/kpanthi/dev/thesis/aquacrop-richards/aquacrop/aquacrop/timestep/run_single_timestep.py", line 229, in solution_single_time_step
    NewCond.depletion, NewCond.taw, NewCond.irr_cum, Irr = irrigation(
  File "/home/kpanthi/dev/thesis/aquacrop-richards/aquacrop/aquacrop/solution/irrigation.py", line 132, in irrigation
    ) = root_zone_water(
  File "/home/kpanthi/dev/thesis/aquacrop-richards/aquacrop/aquacrop/solution/root_zone_water.py", line 149, in root_zone_water
    assert comp_sto > 0
AssertionError
"""

The above exception was the direct cause of the following exception:

Traceback (most recent call last):
  File "/home/kpanthi/dev/thesis/aquacrop-richards/aquacrop/compute_water_balance.py", line 72, in <module>
    main()
  File "/home/kpanthi/dev/thesis/aquacrop-richards/aquacrop/compute_water_balance.py", line 68, in main
    compute_balance_process(hourly, use_richards)
  File "/home/kpanthi/dev/thesis/aquacrop-richards/aquacrop/compute_water_balance.py", line 36, in compute_balance_process
    for result in executor.map(run_simulation_and_get_balance, allargs):
  File "/home/kpanthi/.conda/envs/drl/lib/python3.10/concurrent/futures/process.py", line 575, in _chain_from_iterable_of_lists
    for element in iterable:
  File "/home/kpanthi/.conda/envs/drl/lib/python3.10/concurrent/futures/_base.py", line 621, in result_iterator
    yield _result_or_cancel(fs.pop())
  File "/home/kpanthi/.conda/envs/drl/lib/python3.10/concurrent/futures/_base.py", line 319, in _result_or_cancel
    return fut.result(timeout)
  File "/home/kpanthi/.conda/envs/drl/lib/python3.10/concurrent/futures/_base.py", line 451, in result
    return self.__get_result()
  File "/home/kpanthi/.conda/envs/drl/lib/python3.10/concurrent/futures/_base.py", line 403, in __get_result
    raise self._exception
AssertionError
srun: error: node0417: task 0: Exited with exit code 1
